Workbook

Sheet Feuille 1
A1: No | B1: No
A2: 1 | B2: 1.1 | C2: ENTREPRENEURS | D2: STATUT | E2: ASSO. | F2: CHANTIER COMMUN EN PREPA | G2: CHANTIER ANTICIPE | J2: MOB | K2: FALSE
A3: 1.5 | B3: 1.2 | C3: BA.R | F3: ECURIES | J3: SOLIVAGE | K3: FALSE
A4: 2 | B4: 1.3 | C4: Simon | F4: ECURIES | J4: CHARPENTE | K4: FALSE
A5: 2.5 | B5: 1.4 | J5: ISOLATION | K5: TRUE
A6: 3 | B6: 1.5 | J6: CHEVRONS | K6: TRUE
A7: 3.5 | B7: 1.6 | C7: =F2 -> CHANTIER COMMUN EN PREPA | D7: =F3 -> ECURIES | J7: HPV | K7: TRUE
A8: 4 | B8: 1.7 | C8: Déscripton du chantier: | D8: localité: | E8: Effectif: | F8: Logistique | G8: Levage | H8: Sécurité | I8: Accès | J8: LATTES | K8: TRUE
A9: 4.5 | B9: 1.8 | C9: Projet de rénovation d'un garage en studio; surface au sol 38 m², action menés: réféction de toiture | D9: Sainte-foy de Peyrolière | E9: 2 | F9: Livraison fournisseur sur chantier | G9: Non, réutilisation des tuiles, stockage sur plateforme echaffaudée | H9: Echaffaudage bas de pente, plateforme 9m² stockage tuile | I9: Echaffaudage | J9: LITEAUX | K9: TRUE
A10: 5 | B10: 1.9 | C10: Tableau des valeurs à remplir (couverture) | E10: Tableau des valeurs à remplir (MOB) | J10: TUILES | K10: TRUE
A11: 5.5 | B11: 2 | C11: Mètre carrés de couverture: | D11: 450 | E11: Mètre linéaire de murs: | F11: No | J11: FAITAGE | K11: TRUE
A12: 6 | B12: 2.1 | C12: Pente: | D12: 28 | E12: Hauteur au faitage: | F12: No | J12: ARETIERS | K12: TRUE
A13: 6.5 | B13: 2.2 | C13: Hauteur à l'égout: | D13: 3 | J13: NOUES | K13: FALSE
A14: 7 | B14: 2.3 | C14: Accès: | D14: Possible echaff
A15: 7.5 | B15: 2.4
A16: 8 | B16: 2.5
A17: 8.5 | B17: 2.6
A18: 9 | B18: 2.7 | C18: =J2 -> MOB | E18: =J3 -> SOLIVAGE | G18: =J4 -> CHARPENTE | I18: =J5 -> ISOLATION | K18: =J6 -> CHEVRONS | M18: =J7 -> HPV | O18: =J8 -> LATTES | Q18: =J9 -> LITEAUX | S18: =J10 -> TUILES | U18: =J11 -> FAITAGE | W18: =J12 -> ARETIERS | Y18: =J13 -> NOUES
A19: 9.5 | B19: 2.8 | C19: Montants | D19: No | E19: PORTEUSES | F19: No | G19: C18 | H19: 100×200 | I19: Sarking | J19: =D11 -> 450 | K19: C18 | L19: 63×100 | M19: HPV | N19: ECRAN R2 HPV 50/1,50M ELOS | O19: C18 | P19: 18×44 | Q19: C18 | R19: LITEAUX sapin 3X4cm | S19: TERREAL | T19: TERREAL - DC12 Double Canal 12 | U19: ML | V19: 30 | W19: ML | X19: 20 | Y19: ML | Z19: 6
A20: 10 | B20: 2.9 | C20: Lisses | D20: No | E20: SOLIVES | F20: No | G20: C24/C30 | H20: 75 × 225 | I20: ISO ENTRE CHEVRONS | J20: No | K20: C24/C30 | L20: No | S20: EDILIANS
A21: 10.5 | B21: 3 | C21: CTVT | D21: No | E21: PLANCHE | F21: No | I21: TRI-ISO | J21: No | K21: Volige | L21: VOLIGES 15mm TR2 TTL ( toutes largeurs )
A22: 11 | B22: 3.1 | C22: EAU INT | D22: No | I22: AUTRES | J22: No
A23: 11.5 | B23: 3.2 | C23: EAU EXT | D23: No
A24: 12 | B24: 3.3 | C24: Sous-Lisses | D24: No
A25: 12.5 | B25: 3.4
A26: 13 | B26: 3.5 | C26: Désignation | E26: def | F26: ref calcul/quantitatif | H26: Coût unitaire TTC | J26: Charge | K26: Marge | L26: Revente facturé | M26: Temps de pose /h | N26: taux | O26: Presta facturé | P26: Total facturé
A27: 13.5 | B27: 3.6 | C27: MOB | D27: =C19 -> Montants | E27: =D19 -> No | F27: =IF(D19="No","No",(F11*D13)*2.2) -> No | G27: /ml | H27: =ifs(D19='Feuille 2'!C34,2.5,D19='Feuille 2'!C43,'Feuille 2'!G43,D19='Feuille 2'!C44,'Feuille 2'!G6,D19='Feuille 2'!C45,'Feuille 2'!G7,D19="No","No") -> No | I27: ml | J27: 0.15 | K27: 0.1 | L27: =IF(F27="No","No",((H27*F27)*(1+J27))*(K27+1)) -> No | M27: =IF(E27="No","No",F27/40) -> No | N27: =500/7 -> 71.428571 | O27: =IF(L27="No","No",(L27*0.1)+(N27*M27)) -> No | P27: =IF(O27="No","No",O27+L27) -> No
A28: 14 | B28: 3.7 | D28: =C20 -> Lisses | E28: =D20 -> No | F28: =IF(D20="No","No",F11*2.5) -> No | G28: /ml | H28: =ifs(D20='Feuille 2'!C35,2.5,D20='Feuille 2'!C44,'Feuille 2'!G44,D20='Feuille 2'!C45,'Feuille 2'!G7,D20='Feuille 2'!C46,'Feuille 2'!G8,D20="No","No") -> No | I28: ml | J28: 0.15 | K28: 0.1 | L28: =IF(F28="No","No",((H28*F28)*(1+J28))*(K28+1)) -> No | M28: =IF(E28="No","No",F28/40) -> No | O28: =IF(L28="No","No",(L28*0.1)+(N28*M28)) -> No | P28: =IF(O28="No","No",O28+L28) -> No
A29: 14.5 | B29: 3.8 | D29: =C21 -> CTVT | E29: =D21 -> No | F29: =IF(F12="No","No",(F12*D13)*1.2) -> No | G29: /m² | H29: =ifs(D21='Feuille 2'!A8,'Feuille 2'!G15,D21="No","No") -> No | I29: =G29 -> /m² | J29: 0.15 | K29: 0.1 | L29: =IF(F29="No","No",((H29*F29)*(1+J29))*(K29+1)) -> No | M29: =IF(E29="No","No",F29/40) -> No | O29: =IF(L29="No","No",(L29*0.1)+(N29*M29)) -> No | P29: =IF(O29="No","No",O29+L29) -> No
A30: 15 | B30: 3.9 | D30: =C22 -> EAU INT | E30: =D22 -> No | F30: =IF(F12="No","No",(F12*D13)*1.2) -> No | G30: /m² | I30: =G30 -> /m² | J30: 0.15 | K30: 0.1 | L30: =IF(F30="No","No",((H30*F30)*(1+J30))*(K30+1)) -> No | M30: =IF(E30="No","No",F30/40) -> No | O30: =IF(L30="No","No",(L30*0.1)+(N30*M30)) -> No | P30: =IF(O30="No","No",O30+L30) -> No
A31: 15.5 | B31: 4 | D31: =C23 -> EAU EXT | E31: =D23 -> No | F31: =IF(F12="No","No",(F12*D13)*1.2) -> No | G31: /m² | I31: =G31 -> /m² | J31: 0.15 | K31: 0.1 | L31: =IF(F31="No","No",((H31*F31)*(1+J31))*(K31+1)) -> No | M31: =IF(E31="No","No",F31/40) -> No | O31: =IF(L31="No","No",(L31*0.1)+(N31*M31)) -> No | P31: =IF(O31="No","No",O31+L31) -> No
A32: 16 | B32: 4.1 | D32: =C24 -> Sous-Lisses | E32: =D24 -> No | F32: =IF(D24="No","No",D24*2.2) -> No | G32: /ml | I32: =G32 -> /ml | J32: 0.15 | K32: 0.1 | L32: =IF(F32="No","No",((H32*F32)*(1+J32))*(K32+1)) -> No | M32: =IF(E32="No","No",F32/40) -> No | O32: =IF(L32="No","No",(L32*0.1)+(N32*M32)) -> No | P32: =IF(O32="No","No",O32+L32) -> No
A33: 16.5 | B33: 4.2 | C33: SOLIVAGE | D33: =E19 -> PORTEUSES | E33: =F19 -> No | F33: No | G33: /ml | I33: =G33 -> /ml | J33: 0.15 | K33: 0.1 | L33: =IF(F33="No","No",((H33*F33)*(1+J33))*(K33+1)) -> No | M33: No | N33: =500/7 -> 71.428571 | O33: =IF(L33="No","No",(L33*0.1)+(N33*M33)) -> No | P33: =IF(O33="No","No",O33+L33) -> No
A34: 17 | B34: 4.3 | D34: =E20 -> SOLIVES | E34: =F20 -> No | F34: No | G34: /ml | I34: =G34 -> /ml | J34: 0.15 | K34: 0.1 | L34: =IF(F34="No","No",((H34*F34)*(1+J34))*(K34+1)) -> No | O34: =IF(L34="No","No",(L34*0.1)+(N34*M34)) -> No | P34: =IF(O34="No","No",O34+L34) -> No
A35: 17.5 | B35: 4.4 | D35: =E21 -> PLANCHE | E35: =F21 -> No | F35: No | G35: /m² | I35: =G35 -> /m² | J35: 0.15 | K35: 0.1 | L35: =IF(F35="No","No",((H35*F35)*(1+J35))*(K35+1)) -> No | M35: No | N35: =500/7 -> 71.428571 | O35: =IF(L35="No","No",(L35*0.1)+(N35*M35)) -> No | P35: =IF(O35="No","No",O35+L35) -> No
A36: 18 | B36: 4.5 | C36: CHARPENTE | D36: =G19 -> C18 | E36: =H19 -> 100×200 | F36: No | G36: /ml | H36: =ifs(E36='Feuille 2'!C38,"no",E36='Feuille 2'!C30,'Feuille 2'!G30,E36='Feuille 2'!C31,'Feuille 2'!G31,E36='Feuille 2'!C32,'Feuille 2'!G32,E36='Feuille 2'!C33,'Feuille 2'!G33,E36='Feuille 2'!C34,'Feuille 2'!G34,E36='Feuille 2'!C35,'Feuille 2'!G35,E36='Feuille 2'!C36,'Feuille 2'!G36,E36='Feuille 2'!C37,'Feuille 2'!G37) -> 9.1 | I36: =G36 -> /ml | J36: 0.15 | K36: 0.1 | L36: =IF(F36="No","No",((H36*F36)*(1+J36))*(K36+1)) -> No | M36: 16 | N36: =500/7 -> 71.428571 | O36: =IF(L36="No","No",(L36*0.1)+(N36*M36)) -> No | P36: =IF(O36="No","No",O36+L36) -> No
A37: 18.5 | B37: 4.6 | D37: =G20 -> C24/C30 | E37: =H20 -> 75 × 225 | F37: 30 | G37: /ml | H37: =ifs(E37='Feuille 2'!C39,'Feuille 2'!G39,E37='Feuille 2'!C38,"No",E37='Feuille 2'!C40,'Feuille 2'!G40,E37='Feuille 2'!C41,'Feuille 2'!G41,E37='Feuille 2'!C42,'Feuille 2'!G42,E37='Feuille 2'!C43,'Feuille 2'!G43,E37='Feuille 2'!C44,'Feuille 2'!G44,E37='Feuille 2'!C45,'Feuille 2'!G45,E37='Feuille 2'!C46,'Feuille 2'!G46,E37='Feuille 2'!C47,'Feuille 2'!G47,E37='Feuille 2'!C48,'Feuille 2'!G48,E37='Feuille 2'!C49,'Feuille 2'!G49,E37='Feuille 2'!C50,'Feuille 2'!G50) -> 15.886 | I37: =G37 -> /ml | J37: 0.15 | K37: 0.1 | L37: =IF(F37="No","No",((H37*F37)*(1+J37))*(K37+1)) -> 602.8737 | O37: =IF(L37="No","No",(L37*0.1)+(N37*M37)) -> 60.28737 | P37: =IF(O37="No","No",O37+L37) -> 663.16107
A38: 19 | B38: 4.7 | C38: ISOLATION | D38: =I19 -> Sarking | E38: =J19 -> 450 | F38: =E38 -> 450 | G38: /m² | H38: 31 | I38: =G38 -> /m² | J38: 0.15 | K38: 0.1 | L38: =IF(F38="No","No",((H38*F38)*(1+J38))*(K38+1)) -> 17646.75 | M38: 80 | N38: =500/7 -> 71.428571 | O38: =IF(L38="No","No",(L38*0.1)+(N38*M38)) -> 7478.9607 | P38: =IF(O38="No","No",O38+L38) -> 25125.711
A39: 19.5 | B39: 4.8 | D39: =I20 -> ISO ENTRE CHEVRONS | E39: =J20 -> No | F39: =IF(J20="No","No",D12*0.9) -> No | G39: /m² | I39: =G39 -> /m² | J39: 0.15 | K39: 0.1 | L39: =IF(F39="No","No",((H39*F39)*(1+J39))*(K39+1)) -> No | O39: =IF(L39="No","No",(L39*0.1)+(N39*M39)) -> No | P39: =IF(O39="No","No",O39+L39) -> No
A40: 20 | B40: 4.9 | D40: =I21 -> TRI-ISO | E40: =J21 -> No | F40: =IF(J21="No","No",D13*1.15) -> No | G40: /m² | I40: =G40 -> /m² | J40: 0.15 | K40: 0.1 | L40: =IF(F40="No","No",((H40*F40)*(1+J40))*(K40+1)) -> No | M40: No | O40: =IF(L40="No","No",(L40*0.1)+(N40*M40)) -> No | P40: =IF(O40="No","No",O40+L40) -> No
...

Sheet Feuille 3

Sheet Feuille 2
A3: def | B3: traitement | C3: section(mm) | D3: nbr | E3: qu | F3: prix | G3: revente | H3: quantitatif | I3: commande
M4: Longueur | N4: Matériau | O4: Type de tête | P4: Produit / Référence | Q4: Conditionnement | R4: Prix ~ € / unité
A5: OSSATURE DOUGLAS NAT. 45X95 RAB4F SEC 18 % | B5: E1 | C5: 45*95 | D5: 1 | E5: ml | F5: 2.9 | G5: =F5*1.27 -> 3.683 | M5: 40 mm | N5: Inox A2 | O5: Tête fraisée | P5: Vis bois Torx Inox 6×40 (Fixtout) | Q5: 100 pcs | R5: ~0,135 € (13,50 € /100)
A6: OSSATURE DOUGLAS NAT. 45X145 RAB4F SEC 18 % | B6: E1 | C6: 45*145 | D6: 1 | E6: ml | F6: 4.5 | G6: =F6*1.27 -> 5.715 | M6: 60 mm | N6: Inox A2 | O6: Tête fraisée | P6: 8 vis inox tête fraisée Torx Ø6 x L.60 mm | Q6: 8 pcs | R6: ~0,87 €/vis
A7: OSSATURE DOUGLAS NAT. 45X220 RAB4F SEC 18 % | B7: E1 | C7: 45*220 | D7: 1 | E7: ml | F7: 6.8 | G7: =F7*1.27 -> 8.636 | M7: 60 mm | N7: Acier zingué | O7: Tête fraisée Torx | P7: Vis à bois bichromatée tête fraisée Torx | Q7: Variable | R7: ~0,056 €*
A8: OSB3 12MM 2.50 X 1.25 PNX 3.125m2 | B8: E19 | C8: 1250*2500 | D8: 1 | E8: m² | F8: =ROUNDUP(95/5.5,0) -> 18 | G8: =F8*1.27 -> 22.86 | M8: 80 mm | N8: Acier | O8: Tête fraisée Torx | P8: 10 Vis Agglo Acier Tête Fraisée Torx 6x80mm - Coteka | Q8: 10 pcs | R8: ~0,50 €/vis
A9: PARE VAPEUR SALOLA AEROVAP SD18 - Rlx75m2 | D9: 75 | E9: m² | F9: 95 | G9: =F9*1.27 -> 120.65 | M9: 80 mm | N9: Inox A2 | O9: Tête fraisée Torx | P9: 100x Vis à bois tête fraisée en Acier inoxydable Torx V2A 6x80mm | Q9: 100 pcs | R9: ~0,24 €/vis
A10: BNR TR CL4 VERT - RABOTE 4 FACES section 45X145mm | B10: E19 | C10: 5.4 | D10: 1 | E10: ml | F10: 7 | G10: =F10*1.27 -> 8.89 | M10: 80 mm | N10: Acier zingué | O10: Demi-ronde Torx | P10: 90 vis acier tête demi‑ronde torx VISSAL | Q10: 90 pcs | R10: ~0,12 €/vis
A11: BNR TR CL4 VERT - RABOTE 4 FACES section 45X220mm | B11: E20 | C11: 5.4 | D11: 1 | E11: ml | F11: 7.3 | G11: =F11*1.27 -> 9.271 | M11: 100 mm | N11: Inox A2 | O11: Tête fraisée Torx | P11: entrepôt du bricolage — inox 50 pcs | Q11: ~24,95 € /50 | R11: ~0,50 €/vis
A12: LAINE DE BOIS SEMIN FLEX PLUS 1.22 x 0.565m ép. 145mm | B12: 505010 | C12: 1.22 | D12: 1 | E12: m² | F12: 13.5 | G12: =F12*1.27 -> 17.145 | M12: 100 mm | N12: Inox A2 | O12: Tête fraisée Torx | P12: prix-de-gros inox 100 pcs | Q12: 31,24 € /100 | R12: ~0,31 €/vis
A13: BARDAGE EPICEA TR CL3 MARRON - PROFIL LINE 125 20 x 125 MM | B13: 206002 | C13: 20*125 | D13: 1 | E13: m² | F13: 24 | G13: =F13*1.27 -> 30.48 | M13: 100 mm | N13: Acier galvanisé | O13: Tête fraisée Torx | P13: prix-de-gros galvanisée 100 pcs | Q13: 12,19 € /100 | R13: ~0,12 €/vis
A14: DELTA PROTEKT BANDE D'ARASE (sur chape) 25m x 0.25 RLX | D14: 25 | E14: ml | F14: 92 | G14: =F14*1.27 -> 116.84 | M14: 120 mm | N14: Acier galvanisé | O14: Tête fraisée Torx | P14: prix-de-gros galvanisée 100 pcs | Q14: 16,61 € /100 | R14: ~0,17 €/vis
A15: ECRAN R2 HPV 50/1,50M ELOS | D15: 75 | E15: m² | F15: 82 | G15: =F15*1.27 -> 104.14 | M15: 120 mm | N15: Inox A2 | O15: Tête fraisée Torx | P15: Sud Bois Vis pour Bois en Inox Classic 6x120 mm | Q15: 100 pcs | R15: ~0,22 €/vis
A16: Produit / Référence | B16: Matériau | C16: Longueur | F16: prix | M16: 140 mm | N16: (présent mais non listé commercialement)** | P16: Vis bois TX Turbodrive Premium 6x140 | Q16: 1 lot | R16: ~32,90 € (lot)
A17: Vis bois Torx Inox 6×40 (Fixtout) | B17: Inox A2 | C17: 40 mm | D17: 1 | E17: u | F17: 0.135 | G17: =F17+0.5 -> 0.635
A18: 8 vis inox tête fraisée Torx Ø6 x L.60 mm | B18: Inox A2 | C18: 60 mm | D18: 1 | E18: u | F18: 0.87 | G18: =F18+0.5 -> 1.37 | M18: Essence | N18: Section (mm) | O18: Usage principal | P18: Longueurs (m) | Q18: Prix ~ €/m linéaire (indicatif) | R18: Remarques
A19: Vis à bois bichromatée tête fraisée Torx | B19: Acier zingué | C19: 60 mm | D19: 1 | E19: u | F19: 0.56 | G19: =F19+0.5 -> 1.06 | M19: Résineux – Sapin / Épicéa | N19: 18×44 | O19: Liteaux | P19: 2,40–3,00 | Q19: ~0,40 € | R19: Bois tendre, standard Bricolage
A20: 10 Vis Agglo Acier Tête Fraisée Torx 6x80mm - Coteka | B20: Acier | C20: 80 mm | D20: 1 | E20: u | F20: 0.5 | G20: =F20+0.5 -> 1 | N20: 27×44 | O20: Liteaux renforcés | P20: 2,40–4,00 | Q20: ~0,60 € | R20: Ossature légère
A21: 100x Vis à bois tête fraisée en Acier inoxydable Torx V2A 6x80mm | B21: Inox A2 | C21: 80 mm | D21: 1 | E21: u | F21: 0.24 | G21: =F21+0.5 -> 0.74 | N21: 38×63 | O21: Ossature | P21: 2,40–5,00 | Q21: ~0,90 € | R21: Usage structure
A22: 90 vis acier tête demi‑ronde torx VISSAL | B22: Acier zingué | C22: 80 mm | D22: 1 | E22: u | F22: 0.12 | G22: =F22+0.5 -> 0.62 | N22: 45×70 | O22: Ossature | P22: 2,40–5,00 | Q22: ~1,10 € | R22: Standard maison bois
A23: entrepôt du bricolage — inox 50 pcs | B23: Inox A2 | C23: 100 mm | D23: 1 | E23: u | F23: 0.5 | G23: =F23+0.5 -> 1 | N23: 45×95 | O23: Solives | P23: 3,00–6,00 | Q23: ~1,50 € | R23: Solivage plancher
A24: prix-de-gros inox 100 pcs | B24: Inox A2 | C24: 100 mm | D24: 1 | E24: u | F24: 0.31 | G24: =F24+0.5 -> 0.81 | N24: 63×100 | O24: Solives | P24: 3,00–6,00 | Q24: ~2,20 € | R24: Charpente légère
A25: prix-de-gros galvanisée 100 pcs | B25: Acier galvanisé | C25: 100 mm | D25: 1 | E25: u | F25: 0.12 | G25: =F25+0.5 -> 0.62 | N25: 75×150 | O25: Poutres | P25: 3,00–6,00 | Q25: ~3,95 € | R25: Bois structurel
A26: prix-de-gros galvanisée 100 pcs | B26: Acier galvanisé | C26: 120 mm | D26: 1 | E26: u | F26: 0.17 | G26: =F26+0.5 -> 0.67 | N26: 100×200 | O26: Charpente | P26: 4,00–6,00 | Q26: ~7,00 € | R26: Poutre porteuse
A27: Sud Bois Vis pour Bois en Inox Classic 6x120 mm | B27: Inox A2 | C27: 120 mm | D27: 1 | E27: u | F27: 0.22 | G27: =F27+0.5 -> 0.72
A28: Vis bois TX Turbodrive Premium 6x140 | B28: (présent mais non listé commercialement)** | C28: 140 mm | D28: 1 | E28: u | F28: 0.33 | G28: =F28+0.5 -> 0.83 | M28: Résineux durables (Douglas) | N28: Section (mm) | O28: Usage principal | P28: Longueurs (m) | Q28: Prix ~ €/m linéaire (TTC) | R28: Source / Remarques
A29: Essence | C29: section(mm) | F29: prix | N29: 38 × 150 | O29: Solivette / petit madrier | P29: 3,60 m – 4,50 m | Q29: ~3,80 € TTC/m | R29: Arrivage Douglas sec – dimensions & prix HT ~3,20 € (≈3,84 € TTC) (Recyc'Eco)
A30: Résineux – Sapin / Épicéa | B30: C18 | C30: 18×44 | D30: 1 | E30: ml | F30: 0.4 | G30: =F30*1.3 -> 0.52 | N30: 38 × 200 | O30: Madrier charpente / coffrage | P30: ~2,00 m | Q30: ~5,75 € TTC/m | R30: Bois direct usine – madrier Douglas 38×200mm (Bois Direct Usine)
B31: C18 | C31: 27×44 | D31: 1 | E31: ml | F31: 0.6 | G31: =F31*1.3 -> 0.78 | N31: 45 × 70 | O31: Ossature légère | P31: 3–5 m (raboté possible) | Q31: ~1,80–2,50 € TTC/m | R31: Disponible chez négociants (raboté 45×70) (UneTerrasse.com)
B32: C18 | C32: 38×63 | D32: 1 | E32: ml | F32: 0.9 | G32: =F32*1.3 -> 1.17 | N32: 45 × 95 | O32: Ossature / mur MOB | P32: 2–5,10 m | Q32: ~4,00 € TTC/m | R32: Montant ossature Douglas Classe 2 (~4 €/m) (Matériaux Naturels)
B33: C18 | C33: 45×70 | D33: 1 | E33: ml | F33: 1.1 | G33: =F33*1.3 -> 1.43 | N33: 45 × 120 | O33: Ossature plus large | P33: 2–5,10 m | Q33: ~4,70–5,80 € TTC/m | R33: Ossature Douglas raboté promos (centralbois.fr)
B34: C18 | C34: 45×95 | D34: 1 | E34: ml | F34: 1.5 | G34: =F34*1.3 -> 1.95 | N34: 45 × 145 | O34: Ossature / structure | P34: 2–5,10 m | Q34: ~4,90–6,25 € TTC/m | R34: Raboté / promos - différents vendeurs (centralbois.fr)
B35: C18 | C35: 63×100 | D35: 1 | E35: ml | F35: 2.2 | G35: =F35*1.3 -> 2.86 | N35: 45 × 220 | O35: Gros ossature / meuble | P35: 3–5,10 m | Q35: ~8,80 € TTC/m | R35: Montant ossature Douglas Classe 2 (larges) (Matériaux Naturels)
B36: C18 | C36: 75×150 | D36: 1 | E36: ml | F36: 3.95 | G36: =F36*1.3 -> 5.135 | N36: 50 × 150 | O36: Bastaing / solive | P36: 3–6 m | Q36: ~4,82–4,95 € TTC/m | R36: Woodlife – Douglas madrier (50×150) (woodlife-scierie.fr)
B37: C18 | C37: 100×200 | D37: 1 | E37: ml | F37: 7 | G37: =F37*1.3 -> 9.1 | N37: 63 × 175 | O37: Solive / charpente | P37: 3–6 m | Q37: ~8,40–8,40 € TTC/m | R37: Tambours madrier Douglas 63×175 (woodlife-scierie.fr)
C38: No | H38: No | N38: 75 × 200 | O38: Poutre structurelle | P38: 3–6 m | Q38: ~10,24 –10,85 € TTC/m | R38: Madrier Douglas 75×200 (woodlife-scierie.fr)
A39: Résineux durables (Douglas) | B39: C24 | C39: 38 × 150 | D39: 1 | E39: ml | F39: 3.8 | G39: =F39*1.3 -> 4.94 | N39: 75 × 225 | O39: Poutre charpente lourde | P39: 5–6 m | Q39: ~11,63–12,22 € TTC/m | R39: Douglas madrier 75×225 (woodlife-scierie.fr)
B40: C24 | C40: 38 × 200 | D40: 1 | E40: ml | F40: 5.75 | G40: =F40*1.3 -> 7.475 | N40: 320 × 90 | O40: Poutre lamellé-collé | P40: 6,00 m | Q40: ~49,82 € TTC/m | R40: Poutre lamellé-collé Douglas segmentée (Partedis Bois et Matériaux)
B41: C24 | C41: 45 × 70 | D41: 1 | E41: ml | F41: 2.5 | G41: =F41*1.3 -> 3.25
B42: C24 | C42: 45 × 95 | D42: 1 | E42: ml | F42: 4 | G42: =F42*1.3 -> 5.2 | M42: Type de tuile | N42: Modèle courant (exemples) | O42: Tuiles / m² | P42: Prix ~ €/m² | Q42: Pente mini | R42: Couleurs disponibles
...
